Workbook

Sheet Apple Stock
D3: Stocks Analysis
E7: APPLE
B8: Comp Name | C8: Ticker | D8: Date | E8: Open | F8: High | G8: Low | H8: Close | I8: Adj Close | J8: Volume | K8: Daily returns | N8: Daily Returns APPLE
B10: Apple | C10: AAPL | D10: 44964 | E10: 150.64 | F10: 155.23 | G10: 150.64 | H10: 154.64999 | I10: 154.41423 | J10: 83322600
B11: Apple | C11: AAPL | D11: 44965 | E11: 153.88 | F11: 154.58 | G11: 151.17 | H11: 151.92 | I11: 151.6884 | J11: 64120100 | K11: =I11-I10/I10 -> 150.6884
B12: Apple | C12: AAPL | D12: 44966 | E12: 153.78 | F12: 154.33 | G12: 150.42 | H12: 150.87 | I12: 150.64 | J12: 56007100 | K12: =I12-I11/I11 -> 149.64
B13: Apple | C13: AAPL | D13: 44967 | E13: 149.46001 | F13: 151.34 | G13: 149.22 | H13: 151.00999 | I13: 151.00999 | J13: 57450700 | K13: =I13-I12/I12 -> 150.00999
B14: Apple | C14: AAPL | D14: 44970 | E14: 150.95 | F14: 154.25999 | G14: 150.92 | H14: 153.85001 | I14: 153.85001 | J14: 62199000 | K14: =I14-I13/I13 -> 152.85001
B15: Apple | C15: AAPL | D15: 44971 | E15: 152.12 | F15: 153.77 | G15: 150.86 | H15: 153.2 | I15: 153.2 | J15: 61707600 | K15: =I15-I14/I14 -> 152.2
B16: Apple | C16: AAPL | D16: 44972 | E16: 153.11 | F16: 155.5 | G16: 152.88 | H16: 155.33 | I16: 155.33 | J16: 65573800 | K16: =I16-I15/I15 -> 154.33
B17: Apple | C17: AAPL | D17: 44973 | E17: 153.50999 | F17: 156.33 | G17: 153.35001 | H17: 153.71001 | I17: 153.71001 | J17: 68167900 | K17: =I17-I16/I16 -> 152.71001
B18: Apple | C18: AAPL | D18: 44974 | E18: 152.35001 | F18: 153 | G18: 150.85001 | H18: 152.55 | I18: 152.55 | J18: 59144100 | K18: =I18-I17/I17 -> 151.55
B19: Apple | C19: AAPL | D19: 44978 | E19: 150.2 | F19: 151.3 | G19: 148.41 | H19: 148.48 | I19: 148.48 | J19: 58867200 | K19: =I19-I18/I18 -> 147.48
B20: Apple | C20: AAPL | D20: 44979 | E20: 148.87 | F20: 149.95 | G20: 147.16 | H20: 148.91 | I20: 148.91 | J20: 51011300 | K20: =I20-I19/I19 -> 147.91
B21: Apple | C21: AAPL | D21: 44980 | E21: 150.09 | F21: 150.34 | G21: 147.24001 | H21: 149.39999 | I21: 149.39999 | J21: 48394200 | K21: =I21-I20/I20 -> 148.39999
B22: Apple | C22: AAPL | D22: 44981 | E22: 147.11 | F22: 147.19 | G22: 145.72 | H22: 146.71001 | I22: 146.71001 | J22: 55469600 | K22: =I22-I21/I21 -> 145.71001
... B27: Apple | C27: AAPL | D27: 44988 | E27: 148.03999 | F27: 151.11 | G27: 147.33 | H27: 151.03 | I27: 151.03 | J27: 70732300 | K27: =I27-I26/I26 -> 150.03
B28: Apple | C28: AAPL | D28: 44991 | E28: 153.78999 | F28: 156.3 | G28: 153.46001 | H28: 153.83 | I28: 153.83 | J28: 87558000 | K28: =I28-I27/I27 -> 152.83 | N28: Volume v/s Closing price APPLE
B29: Apple | C29: AAPL | D29: 44992 | E29: 153.7 | F29: 154.03 | G29: 151.13 | H29: 151.60001 | I29: 151.60001 | J29: 56182000 | K29: =I29-I28/I28 -> 150.60001
B30: Apple | C30: AAPL | D30: 44993 | E30: 152.81 | F30: 153.47 | G30: 151.83 | H30: 152.87 | I30: 152.87 | J30: 47204800 | K30: =I30-I29/I29 -> 151.87
B31: Apple | C31: AAPL | D31: 44994 | E31: 153.56 | F31: 154.53999 | G31: 150.23 | H31: 150.59 | I31: 150.59 | J31: 53833600 | K31: =I31-I30/I30 -> 149.59
B32: Apple | C32: AAPL | D32: 44995 | E32: 150.21001 | F32: 150.94 | G32: 147.61 | H32: 148.5 | I32: 148.5 | J32: 68572400 | K32: =I32-I31/I31 -> 147.5
B33: Apple | C33: AAPL | D33: 44998 | E33: 147.81 | F33: 153.14 | G33: 147.7 | H33: 150.47 | I33: 150.47 | J33: 84457100 | K33: =I33-I32/I32 -> 149.47
B34: Apple | C34: AAPL | D34: 44999 | E34: 151.28 | F34: 153.39999 | G34: 150.10001 | H34: 152.59 | I34: 152.59 | J34: 73695900 | K34: =I34-I33/I33 -> 151.59
B35: Apple | C35: AAPL | D35: 45000 | E35: 151.19 | F35: 153.25 | G35: 149.92 | H35: 152.99001 | I35: 152.99001 | J35: 77167900 | K35: =I35-I34/I34 -> 151.99001
B36: Apple | C36: AAPL | D36: 45001 | E36: 152.16 | F36: 156.46001 | G36: 151.64 | H36: 155.85001 | I36: 155.85001 | J36: 76161100 | K36: =I36-I35/I35 -> 154.85001
B37: Apple | C37: AAPL | D37: 45002 | E37: 156.08 | F37: 156.74001 | G37: 154.28 | H37: 155 | I37: 155 | J37: 98944600 | K37: =I37-I36/I36 -> 154
B38: Apple | C38: AAPL | D38: 45005 | E38: 155.07001 | F38: 157.82001 | G38: 154.14999 | H38: 157.39999 | I38: 157.39999 | J38: 73641400 | K38: =I38-I37/I37 -> 156.39999
B39: Apple | C39: AAPL | D39: 45006 | E39: 157.32001 | F39: 159.39999 | G39: 156.53999 | H39: 159.28 | I39: 159.28 | J39: 73938300 | K39: =I39-I38/I38 -> 158.28
B40: Apple | C40: AAPL | D40: 45007 | E40: 159.3 | F40: 162.14 | G40: 157.81 | H40: 157.83 | I40: 157.83 | J40: 75701800 | K40: =I40-I39/I39 -> 156.83
... B48: Apple | C48: AAPL | D48: 45019 | E48: 164.27 | F48: 166.28999 | G48: 164.22 | H48: 166.17 | I48: 166.17 | J48: 56976200 | K48: =I48-I47/I47 -> 165.17
B49: Apple | C49: AAPL | D49: 45020 | E49: 166.60001 | F49: 166.84 | G49: 165.11 | H49: 165.63 | I49: 165.63 | J49: 46278300 | K49: =I49-I48/I48 -> 164.63 | N49: Candle Stick Chart Open High Low Close APPLE
B50: Apple | C50: AAPL | D50: 45021 | E50: 164.74001 | F50: 165.05 | G50: 161.8 | H50: 163.75999 | I50: 163.75999 | J50: 51511700 | K50: =I50-I49/I49 -> 162.75999
B51: Apple | C51: AAPL | D51: 45022 | E51: 162.42999 | F51: 164.96001 | G51: 162 | H51: 164.66 | I51: 164.66 | J51: 45390100 | K51: =I51-I50/I50 -> 163.66
B52: Apple | C52: AAPL | D52: 45026 | E52: 161.42 | F52: 162.03 | G52: 160.08 | H52: 162.03 | I52: 162.03 | J52: 47716900 | K52: =I52-I51/I51 -> 161.03
B53: Apple | C53: AAPL | D53: 45027 | E53: 162.35001 | F53: 162.36 | G53: 160.50999 | H53: 160.8 | I53: 160.8 | J53: 47644200 | K53: =I53-I52/I52 -> 159.8
B54: Apple | C54: AAPL | D54: 45028 | E54: 161.22 | F54: 162.06 | G54: 159.78 | H54: 160.10001 | I54: 160.10001 | J54: 50133100 | K54: =I54-I53/I53 -> 159.10001
B55: Apple | C55: AAPL | D55: 45029 | E55: 161.63 | F55: 165.8 | G55: 161.42 | H55: 165.56 | I55: 165.56 | J55: 68445600 | K55: =I55-I54/I54 -> 164.56
B56: Apple | C56: AAPL | D56: 45030 | E56: 164.59 | F56: 166.32001 | G56: 163.82001 | H56: 165.21001 | I56: 165.21001 | J56: 49386500 | K56: =I56-I55/I55 -> 164.21001
B57: Apple | C57: AAPL | D57: 45033 | E57: 165.09 | F57: 165.39 | G57: 164.03 | H57: 165.23 | I57: 165.23 | J57: 41516200 | K57: =I57-I56/I56 -> 164.23
...

Sheet Microsoft Stock
E3: MICROSOFT
B4: ='Apple Stock'!B8 -> Comp Name | C4: ='Apple Stock'!C8 -> Ticker | D4: ='Apple Stock'!D8 -> Date | E4: ='Apple Stock'!E8 -> Open | F4: ='Apple Stock'!F8 -> High | G4: ='Apple Stock'!G8 -> Low | H4: ='Apple Stock'!H8 -> Close | I4: ='Apple Stock'!I8 -> Adj Close | ... K4: ='Apple Stock'!K8 -> Daily returns | N4: Daily Returns MICROSOFT
B6: Microsoft | C6: MSFT | D6: 44964 | E6: 260.53 | F6: 268.76999 | G6: 260.07999 | H6: 267.56 | I6: 266.89151 | J6: 50841400
B7: Microsoft | C7: MSFT | D7: 44965 | E7: 273.20001 | F7: 276.76001 | G7: 266.20999 | H7: 266.73001 | I7: 266.0636 | J7: 54686000 | K7: =I7-I6/I6 -> 265.0636
B8: Microsoft | C8: MSFT | D8: 44966 | E8: 273.79999 | F8: 273.98001 | G8: 262.79999 | H8: 263.62 | I8: 262.96136 | J8: 42375100 | K8: =I8-I7/I7 -> 261.96136
B9: Microsoft | C9: MSFT | D9: 44967 | E9: 261.53 | F9: 264.09 | G9: 260.66 | H9: 263.10001 | I9: 262.44266 | J9: 25818500 | K9: =I9-I8/I8 -> 261.44266
B10: Microsoft | C10: MSFT | D10: 44970 | E10: 267.64001 | F10: 274.60001 | G10: 267.14999 | H10: 271.32001 | I10: 270.64212 | J10: 44630900 | K10: =I10-I9/I9 -> 269.64212
B11: Microsoft | C11: MSFT | D11: 44971 | E11: 272.67001 | F11: 274.97 | G11: 269.28 | H11: 272.17001 | I11: 271.49002 | J11: 37047900 | K11: =I11-I10/I10 -> 270.49002
B12: Microsoft | C12: MSFT | D12: 44972 | E12: 268.32001 | F12: 270.73001 | G12: 266.17999 | H12: 269.32001 | I12: 269.32001 | J12: 28922400 | K12: =I12-I11/I11 -> 268.32001
B13: Microsoft | C13: MSFT | D13: 44973 | E13: 264.01999 | F13: 266.73999 | G13: 261.89999 | H13: 262.14999 | I13: 262.14999 | J13: 29603600 | K13: =I13-I12/I12 -> 261.14999
B14: Microsoft | C14: MSFT | D14: 44974 | E14: 259.39001 | F14: 260.09 | G14: 256 | H14: 258.06 | I14: 258.06 | J14: 30000100 | K14: =I14-I13/I13 -> 257.06
B15: Microsoft | C15: MSFT | D15: 44978 | E15: 254.48 | F15: 255.49001 | G15: 251.59 | H15: 252.67 | I15: 252.67 | J15: 28397400 | K15: =I15-I14/I14 -> 251.67
B16: Microsoft | C16: MSFT | D16: 44979 | E16: 254.09 | F16: 254.34 | G16: 250.34 | H16: 251.50999 | I16: 251.50999 | J16: 22491100 | K16: =I16-I15/I15 -> 250.50999
B17: Microsoft | C17: MSFT | D17: 44980 | E17: 255.56 | F17: 256.84 | G17: 250.48 | H17: 254.77 | I17: 254.77 | J17: 29219100 | K17: =I17-I16/I16 -> 253.77
B18: Microsoft | C18: MSFT | D18: 44981 | E18: 249.96001 | F18: 251 | G18: 248.10001 | H18: 249.22 | I18: 249.22 | J18: 24990900 | K18: =I18-I17/I17 -> 248.22
... B21: Microsoft | C21: MSFT | D21: 44986 | E21: 250.75999 | F21: 250.92999 | G21: 245.78999 | H21: 246.27 | I21: 246.27 | J21: 27565300 | K21: =I21-I20/I20 -> 245.27
B22: Microsoft | C22: MSFT | D22: 44987 | E22: 246.55 | F22: 251.39999 | G22: 245.61 | H22: 251.11 | I22: 251.11 | J22: 24808200 | K22: =I22-I21/I21 -> 250.11 | N22: Volume v/s Closing price MICROSOFT
B23: Microsoft | C23: MSFT | D23: 44988 | E23: 252.19 | F23: 255.62 | G23: 251.39 | H23: 255.28999 | I23: 255.28999 | J23: 30760100 | K23: =I23-I22/I22 -> 254.28999
B24: Microsoft | C24: MSFT | D24: 44991 | E24: 256.42999 | F24: 260.12 | G24: 255.98 | H24: 256.87 | I24: 256.87 | J24: 24109800 | K24: =I24-I23/I23 -> 255.87
B25: Microsoft | C25: MSFT | D25: 44992 | E25: 256.29999 | F25: 257.69 | G25: 253.39 | H25: 254.14999 | I25: 254.14999 | J25: 21473200 | K25: =I25-I24/I24 -> 253.14999
B26: Microsoft | C26: MSFT | D26: 44993 | E26: 254.03999 | F26: 254.53999 | G26: 250.81 | H26: 253.7 | I26: 253.7 | J26: 17340200 | K26: =I26-I25/I25 -> 252.7
B27: Microsoft | C27: MSFT | D27: 44994 | E27: 255.82001 | F27: 259.56 | G27: 251.58 | H27: 252.32001 | I27: 252.32001 | J27: 26653400 | K27: =I27-I26/I26 -> 251.32001
B28: Microsoft | C28: MSFT | D28: 44995 | E28: 251.08 | F28: 252.78999 | G28: 247.60001 | H28: 248.59 | I28: 248.59 | J28: 28333900 | K28: =I28-I27/I27 -> 247.59
B29: Microsoft | C29: MSFT | D29: 44998 | E29: 247.39999 | F29: 257.91 | G29: 245.73 | H29: 253.92 | I29: 253.92 | J29: 33339700 | K29: =I29-I28/I28 -> 252.92
B30: Microsoft | C30: MSFT | D30: 44999 | E30: 256.75 | F30: 261.07001 | G30: 255.86 | H30: 260.79001 | I30: 260.79001 | J30: 33620300 | K30: =I30-I29/I29 -> 259.79001
B31: Microsoft | C31: MSFT | D31: 45000 | E31: 259.98001 | F31: 266.48001 | G31: 259.20999 | H31: 265.44 | I31: 265.44 | J31: 46028000 | K31: =I31-I30/I30 -> 264.44
B32: Microsoft | C32: MSFT | D32: 45001 | E32: 265.20999 | F32: 276.56 | G32: 263.28 | H32: 276.20001 | I32: 276.20001 | J32: 54768800 | K32: =I32-I31/I31 -> 275.20001
B33: Microsoft | C33: MSFT | D33: 45002 | E33: 278.26001 | F33: 283.32999 | G33: 276.32001 | H33: 279.42999 | I33: 279.42999 | J33: 69527400 | K33: =I33-I32/I32 -> 278.42999
B34: Microsoft | C34: MSFT | D34: 45005 | E34: 276.98001 | F34: 277.48001 | G34: 269.85001 | H34: 272.23001 | I34: 272.23001 | J34: 43466600 | K34: =I34-I33/I33 -> 271.23001
... B41: Microsoft | C41: MSFT | D41: 45014 | E41: 278.95999 | F41: 281.14001 | G41: 278.41 | H41: 280.51001 | I41: 280.51001 | J41: 25087000 | K41: =I41-I40/I40 -> 279.51001
B42: Microsoft | C42: MSFT | D42: 45015 | E42: 284.23001 | F42: 284.45999 | G42: 281.48001 | H42: 284.04999 | I42: 284.04999 | J42: 25053400 | K42: =I42-I41/I41 -> 283.04999 | N42: Candle Stick Chart Open High Low Close Microsoft
B43: Microsoft | C43: MSFT | D43: 45016 | E43: 283.73001 | F43: 289.26999 | G43: 283 | H43: 288.29999 | I43: 288.29999 | J43: 32766000 | K43: =I43-I42/I42 -> 287.29999
B44: Microsoft | C44: MSFT | D44: 45019 | E44: 286.51999 | F44: 288.26999 | G44: 283.95001 | H44: 287.23001 | I44: 287.23001 | J44: 24883300 | K44: =I44-I43/I43 -> 286.23001
B45: Microsoft | C45: MSFT | D45: 45020 | E45: 287.23001 | F45: 290.45001 | G45: 285.67001 | H45: 287.17999 | I45: 287.17999 | J45: 25824300 | K45: =I45-I44/I44 -> 286.17999
B46: Microsoft | C46: MSFT | D46: 45021 | E46: 285.85001 | F46: 287.14999 | G46: 282.92001 | H46: 284.34 | I46: 284.34 | J46: 22064800 | K46: =I46-I45/I45 -> 283.34
B47: Microsoft | C47: MSFT | D47: 45022 | E47: 283.20999 | F47: 292.07999 | G47: 282.03 | H47: 291.60001 | I47: 291.60001 | J47: 29770300 | K47: =I47-I46/I46 -> 290.60001
B48: Microsoft | C48: MSFT | D48: 45026 | E48: 289.20999 | F48: 289.60001 | G48: 284.70999 | H48: 289.39001 | I48: 289.39001 | J48: 23103000 | K48: =I48-I47/I47 -> 288.39001
B49: Microsoft | C49: MSFT | D49: 45027 | E49: 285.75 | F49: 285.98001 | G49: 281.64001 | H49: 282.82999 | I49: 282.82999 | J49: 27276600 | K49: =I49-I48/I48 -> 281.82999
B50: Microsoft | C50: MSFT | D50: 45028 | E50: 284.79001 | F50: 287.01001 | G50: 281.95999 | H50: 283.48999 | I50: 283.48999 | J50: 27403400 | K50: =I50-I49/I49 -> 282.48999
B51: Microsoft | C51: MSFT | D51: 45029 | E51: 283.59 | F51: 289.89999 | G51: 283.17001 | H51: 289.84 | I51: 289.84 | J51: 24222700 | K51: =I51-I50/I50 -> 288.84
...

Sheet Netflix Stock
F3: NETFLIX
B4: ='Apple Stock'!B8 -> Comp Name | C4: ='Apple Stock'!C8 -> Ticker | D4: ='Apple Stock'!D8 -> Date | E4: ='Apple Stock'!E8 -> Open | F4: ='Apple Stock'!F8 -> High | G4: ='Apple Stock'!G8 -> Low | H4: ='Apple Stock'!H8 -> Close | I4: ='Apple Stock'!I8 -> Adj Close | ... K4: ='Apple Stock'!K8 -> Daily returns
N5: Daily Returns NETFLIX
B6: Netflix | C6: NFLX | D6: 44964 | E6: 358.51001 | F6: 364.17999 | G6: 354.17999 | H6: 362.95001 | I6: 362.95001 | J6: 6289400
B7: Netflix | C7: NFLX | D7: 44965 | E7: 360.01999 | F7: 368.19 | G7: 358.31 | H7: 366.82999 | I7: 366.82999 | J7: 6253200 | K7: =I7-I6/I6 -> 365.82999
B8: Netflix | C8: NFLX | D8: 44966 | E8: 372.41 | F8: 373.82999 | G8: 361.73999 | H8: 362.5 | I8: 362.5 | J8: 6901100 | K8: =I8-I7/I7 -> 361.5
B9: Netflix | C9: NFLX | D9: 44967 | E9: 359.16 | F9: 362.14001 | G9: 347.14001 | H9: 347.35999 | I9: 347.35999 | J9: 7291100 | K9: =I9-I8/I8 -> 346.35999
B10: Netflix | C10: NFLX | D10: 44970 | E10: 349.5 | F10: 359.70001 | G10: 344.25 | H10: 358.57001 | I10: 358.57001 | J10: 7134400 | K10: =I10-I9/I9 -> 357.57001
B11: Netflix | C11: NFLX | D11: 44971 | E11: 357.54999 | F11: 363.75 | G11: 353.39999 | H11: 359.95999 | I11: 359.95999 | J11: 4624800 | K11: =I11-I10/I10 -> 358.95999
B12: Netflix | C12: NFLX | D12: 44972 | E12: 356.63 | F12: 362.88 | G12: 354.23999 | H12: 361.42001 | I12: 361.42001 | J12: 3966000 | K12: =I12-I11/I11 -> 360.42001
B13: Netflix | C13: NFLX | D13: 44973 | E13: 355 | F13: 361.5 | G13: 350.31 | H13: 350.70999 | I13: 350.70999 | J13: 5215700 | K13: =I13-I12/I12 -> 349.70999
B14: Netflix | C14: NFLX | D14: 44974 | E14: 347.91 | F14: 349 | G14: 342.44 | H14: 347.95999 | I14: 347.95999 | J14: 5294700 | K14: =I14-I13/I13 -> 346.95999
B15: Netflix | C15: NFLX | D15: 44978 | E15: 342.85001 | F15: 344.13 | G15: 336.42001 | H15: 337.5 | I15: 337.5 | J15: 5710300 | K15: =I15-I14/I14 -> 336.5
B16: Netflix | C16: NFLX | D16: 44979 | E16: 337.5 | F16: 341.91 | G16: 332.82001 | H16: 334.88 | I16: 334.88 | J16: 4546200 | K16: =I16-I15/I15 -> 333.88
B17: Netflix | C17: NFLX | D17: 44980 | E17: 331.23001 | F17: 331.28 | G17: 314.29999 | H17: 323.64999 | I17: 323.64999 | J17: 13238700 | K17: =I17-I16/I16 -> 322.64999
B18: Netflix | C18: NFLX | D18: 44981 | E18: 319.29999 | F18: 321.5 | G18: 314.51999 | H18: 317.14999 | I18: 317.14999 | J18: 6830700 | K18: =I18-I17/I17 -> 316.14999
... B23: Netflix | C23: NFLX | D23: 44988 | E23: 315.45001 | F23: 317.48999 | G23: 310.82001 | H23: 315.17999 | I23: 315.17999 | J23: 5953300 | K23: =I23-I22/I22 -> 314.17999
B24: Netflix | C24: NFLX | D24: 44991 | E24: 317 | F24: 323.29999 | G24: 311.84 | H24: 312.03 | I24: 312.03 | J24: 5660700 | K24: =I24-I23/I23 -> 311.03 | N24: Volume v/s Closing price NETFLIX
B25: Netflix | C25: NFLX | D25: 44992 | E25: 312.67999 | F25: 314.29999 | G25: 306.62 | H25: 308.47 | I25: 308.47 | J25: 4553100 | K25: =I25-I24/I24 -> 307.47
B26: Netflix | C26: NFLX | D26: 44993 | E26: 309.29001 | F26: 311.82999 | G26: 305.75 | H26: 311.79001 | I26: 311.79001 | J26: 3479500 | K26: =I26-I25/I25 -> 310.79001
B27: Netflix | C27: NFLX | D27: 44994 | E27: 312.07999 | F27: 312.51001 | G27: 294.88 | H27: 297.78 | I27: 297.78 | J27: 7443400 | K27: =I27-I26/I26 -> 296.78
B28: Netflix | C28: NFLX | D28: 44995 | E28: 297.89999 | F28: 298.79001 | G28: 289 | H28: 292.76001 | I28: 292.76001 | J28: 5759300 | K28: =I28-I27/I27 -> 291.76001
B29: Netflix | C29: NFLX | D29: 44998 | E29: 287.34 | F29: 299.23999 | G29: 285.32999 | H29: 293.51001 | I29: 293.51001 | J29: 6292400 | K29: =I29-I28/I28 -> 292.51001
B30: Netflix | C30: NFLX | D30: 44999 | E30: 295.97 | F30: 297.45001 | G30: 290.31 | H30: 294.94 | I30: 294.94 | J30: 5956700 | K30: =I30-I29/I29 -> 293.94
B31: Netflix | C31: NFLX | D31: 45000 | E31: 292.51001 | F31: 306.31 | G31: 292.28 | H31: 303.79001 | I31: 303.79001 | J31: 9215300 | K31: =I31-I30/I30 -> 302.79001
B32: Netflix | C32: NFLX | D32: 45001 | E32: 304.75 | F32: 316.60001 | G32: 301.70999 | H32: 310.06 | I32: 310.06 | J32: 7903700 | K32: =I32-I31/I31 -> 309.06
B33: Netflix | C33: NFLX | D33: 45002 | E33: 310.06 | F33: 310.76001 | G33: 300 | H33: 303.5 | I33: 303.5 | J33: 6918800 | K33: =I33-I32/I32 -> 302.5
B34: Netflix | C34: NFLX | D34: 45005 | E34: 299.79001 | F34: 307.5 | G34: 296 | H34: 305.13 | I34: 305.13 | J34: 5113400 | K34: =I34-I33/I33 -> 304.13
B35: Netflix | C35: NFLX | D35: 45006 | E35: 306.32001 | F35: 307.92001 | G35: 300.42999 | H35: 305.79001 | I35: 305.79001 | J35: 4886300 | K35: =I35-I34/I34 -> 304.79001
B36: Netflix | C36: NFLX | D36: 45007 | E36: 306.31 | F36: 306.45001 | G36: 293.54001 | H36: 293.89999 | I36: 293.89999 | J36: 5808000 | K36: =I36-I35/I35 -> 292.89999
... B41: Netflix | C41: NFLX | D41: 45014 | E41: 326.29001 | F41: 332.85001 | G41: 325.73001 | H41: 332.03 | I41: 332.03 | J41: 6287300 | K41: =I41-I40/I40 -> 331.03
B42: Netflix | C42: NFLX | D42: 45015 | E42: 340.26999 | F42: 343.29001 | G42: 335.29999 | H42: 338.42999 | I42: 338.42999 | J42: 7131500 | K42: =I42-I41/I41 -> 337.42999 | N42: Candle Stick Chart Open High Low Close NETFLIX
B43: Netflix | C43: NFLX | D43: 45016 | E43: 340.04999 | F43: 345.84 | G43: 337.20001 | H43: 345.48001 | I43: 345.48001 | J43: 5610200 | K43: =I43-I42/I42 -> 344.48001
B44: Netflix | C44: NFLX | D44: 45019 | E44: 341.82999 | F44: 348.57999 | G44: 340.39999 | H44: 348.28 | I44: 348.28 | J44: 4413700 | K44: =I44-I43/I43 -> 347.28
B45: Netflix | C45: NFLX | D45: 45020 | E45: 348.48999 | F45: 349.79999 | G45: 343.95001 | H45: 346.75 | I45: 346.75 | J45: 3298100 | K45: =I45-I44/I44 -> 345.75
B46: Netflix | C46: NFLX | D46: 45021 | E46: 345.29999 | F46: 345.42999 | G46: 336.25 | H46: 342.35001 | I46: 342.35001 | J46: 4205500 | K46: =I46-I45/I45 -> 341.35001
B47: Netflix | C47: NFLX | D47: 45022 | E47: 339.34 | F47: 340.48001 | G47: 332.63 | H47: 339.32999 | I47: 339.32999 | J47: 4660500 | K47: =I47-I46/I46 -> 338.32999
B48: Netflix | C48: NFLX | D48: 45026 | E48: 335.26999 | F48: 339.88 | G48: 333.35999 | H48: 338.98999 | I48: 338.98999 | J48: 2657900 | K48: =I48-I47/I47 -> 337.98999
B49: Netflix | C49: NFLX | D49: 45027 | E49: 343.45001 | F49: 347.14001 | G49: 337.64001 | H49: 338.20999 | I49: 338.20999 | J49: 4044800 | K49: =I49-I48/I48 -> 337.20999
B50: Netflix | C50: NFLX | D50: 45028 | E50: 340.81 | F50: 342.79999 | G50: 330.04001 | H50: 331.03 | I50: 331.03 | J50: 3965400 | K50: =I50-I49/I49 -> 330.03
...

Sheet Google Stock
F3: Google
B4: ='Apple Stock'!B8 -> Comp Name | C4: ='Apple Stock'!C8 -> Ticker | D4: ='Apple Stock'!D8 -> Date | E4: ='Apple Stock'!E8 -> Open | F4: ='Apple Stock'!F8 -> High | G4: ='Apple Stock'!G8 -> Low | H4: ='Apple Stock'!H8 -> Close | I4: ='Apple Stock'!I8 -> Adj Close | ... K4: ='Apple Stock'!K8 -> Daily returns
N5: Daily Returns GOOGLE
B6: Google | C6: GOOG | D6: 44964 | E6: 103.63 | F6: 108.67 | G6: 103.548 | H6: 108.04 | I6: 108.04 | J6: 33738800
B7: Google | C7: GOOG | D7: 44965 | E7: 102.69 | F7: 103.58 | G7: 98.455002 | H7: 100 | I7: 100 | J7: 73546000 | K7: =I7-I6/I6 -> 99
B8: Google | C8: GOOG | D8: 44966 | E8: 100.54 | F8: 100.61 | G8: 93.860001 | H8: 95.459999 | I8: 95.459999 | J8: 97798600 | K8: =I8-I7/I7 -> 94.459999
B9: Google | C9: GOOG | D9: 44967 | E9: 95.739998 | F9: 97.019997 | G9: 94.529999 | H9: 94.860001 | I9: 94.860001 | J9: 49325300 | K9: =I9-I8/I8 -> 93.860001
B10: Google | C10: GOOG | D10: 44970 | E10: 95.010002 | F10: 95.349998 | G10: 94.050003 | H10: 95 | I10: 95 | J10: 43116600 | K10: =I10-I9/I9 -> 94
B11: Google | C11: GOOG | D11: 44971 | E11: 94.660004 | F11: 95.175003 | G11: 92.650002 | H11: 94.949997 | I11: 94.949997 | J11: 42513100 | K11: =I11-I10/I10 -> 93.949997
B12: Google | C12: GOOG | D12: 44972 | E12: 94.739998 | F12: 97.339996 | G12: 94.360001 | H12: 97.099998 | I12: 97.099998 | J12: 36964500 | K12: =I12-I11/I11 -> 96.099998
B13: Google | C13: GOOG | D13: 44973 | E13: 95.540001 | F13: 97.879997 | G13: 94.970001 | H13: 95.779999 | I13: 95.779999 | J13: 35642100 | K13: =I13-I12/I12 -> 94.779999
B14: Google | C14: GOOG | D14: 44974 | E14: 95.07 | F14: 95.75 | G14: 93.449997 | H14: 94.589996 | I14: 94.589996 | J14: 31095100 | K14: =I14-I13/I13 -> 93.589996
B15: Google | C15: GOOG | D15: 44978 | E15: 93.239998 | F15: 93.415001 | G15: 92 | H15: 92.050003 | I15: 92.050003 | J15: 28367200 | K15: =I15-I14/I14 -> 91.050003
B16: Google | C16: GOOG | D16: 44979 | E16: 91.933998 | F16: 92.360001 | G16: 90.870003 | H16: 91.800003 | I16: 91.800003 | J16: 29891100 | K16: =I16-I15/I15 -> 90.800003
B17: Google | C17: GOOG | D17: 44980 | E17: 92.129997 | F17: 92.129997 | G17: 90.010002 | H17: 91.07 | I17: 91.07 | J17: 32423700 | K17: =I17-I16/I16 -> 90.07
B18: Google | C18: GOOG | D18: 44981 | E18: 89.629997 | F18: 90.129997 | G18: 88.860001 | H18: 89.349998 | I18: 89.349998 | J18: 31295600 | K18: =I18-I17/I17 -> 88.349998
... B24: Google | C24: GOOG | D24: 44991 | E24: 94.360001 | F24: 96.300003 | G24: 94.300003 | H24: 95.580002 | I24: 95.580002 | J24: 28288200 | K24: =I24-I23/I23 -> 94.580002
B25: Google | C25: GOOG | D25: 44992 | E25: 95.419998 | F25: 96.089996 | G25: 93.844002 | H25: 94.169998 | I25: 94.169998 | J25: 24101500 | K25: =I25-I24/I24 -> 93.169998 | N25: Volume v/s Closing price GOOGLE
B26: Google | C26: GOOG | D26: 44993 | E26: 94.404999 | F26: 96.239998 | G26: 94.404999 | H26: 94.650002 | I26: 94.650002 | J26: 25395200 | K26: =I26-I25/I25 -> 93.650002
B27: Google | C27: GOOG | D27: 44994 | E27: 94.489998 | F27: 95.919998 | G27: 92.355003 | H27: 92.660004 | I27: 92.660004 | J27: 24438900 | K27: =I27-I26/I26 -> 91.660004
B28: Google | C28: GOOG | D28: 44995 | E28: 92.5 | F28: 93.18 | G28: 90.800003 | H28: 91.010002 | I28: 91.010002 | J28: 32850100 | K28: =I28-I27/I27 -> 90.010002
B29: Google | C29: GOOG | D29: 44998 | E29: 90.565002 | F29: 93.080002 | G29: 89.940002 | H29: 91.660004 | I29: 91.660004 | J29: 31508600 | K29: =I29-I28/I28 -> 90.660004
B30: Google | C30: GOOG | D30: 44999 | E30: 93.07 | F30: 94.830002 | G30: 92.779999 | H30: 94.25 | I30: 94.25 | J30: 32303900 | K30: =I30-I29/I29 -> 93.25
B31: Google | C31: GOOG | D31: 45000 | E31: 93.540001 | F31: 97.25 | G31: 93.040001 | H31: 96.550003 | I31: 96.550003 | J31: 38367300 | K31: =I31-I30/I30 -> 95.550003
B32: Google | C32: GOOG | D32: 45001 | E32: 96.57 | F32: 101.97 | G32: 95.870003 | H32: 101.07 | I32: 101.07 | J32: 54499500 | K32: =I32-I31/I31 -> 100.07
B33: Google | C33: GOOG | D33: 45002 | E33: 100.84 | F33: 103.49 | G33: 100.75 | H33: 102.46 | I33: 102.46 | J33: 76140300 | K33: =I33-I32/I32 -> 101.46
B34: Google | C34: GOOG | D34: 45005 | E34: 101.06 | F34: 102.58 | G34: 100.79 | H34: 101.93 | I34: 101.93 | J34: 26033900 | K34: =I34-I33/I33 -> 100.93
B35: Google | C35: GOOG | D35: 45006 | E35: 101.98 | F35: 105.96 | G35: 101.86 | H35: 105.84 | I35: 105.84 | J35: 33122800 | K35: =I35-I34/I34 -> 104.84
B36: Google | C36: GOOG | D36: 45007 | E36: 105.14 | F36: 107.51 | G36: 104.21 | H36: 104.22 | I36: 104.22 | J36: 32336900 | K36: =I36-I35/I35 -> 103.22
B37: Google | C37: GOOG | D37: 45008 | E37: 105.89 | F37: 107.101 | G37: 105.41 | H37: 106.26 | I37: 106.26 | J37: 31385800 | K37: =I37-I36/I36 -> 105.26
... B44: Google | C44: GOOG | D44: 45019 | E44: 102.67 | F44: 104.95 | G44: 102.38 | H44: 104.91 | I44: 104.91 | J44: 20719900 | K44: =I44-I43/I43 -> 103.91
B45: Google | C45: GOOG | D45: 45020 | E45: 104.84 | F45: 106.1 | G45: 104.6 | H45: 105.12 | I45: 105.12 | J45: 20377200 | K45: =I45-I44/I44 -> 104.12 | O45: Candle Stick Chart Open High Low Close GOOGLE
B46: Google | C46: GOOG | D46: 45021 | E46: 106.12 | F46: 106.54 | G46: 104.102 | H46: 104.95 | I46: 104.95 | J46: 21864200 | K46: =I46-I45/I45 -> 103.95
B47: Google | C47: GOOG | D47: 45022 | E47: 105.77 | F47: 109.63 | G47: 104.815 | H47: 108.9 | I47: 108.9 | J47: 34684200 | K47: =I47-I46/I46 -> 107.9
B48: Google | C48: GOOG | D48: 45026 | E48: 107.39 | F48: 107.97 | G48: 105.6 | H48: 106.95 | I48: 106.95 | J48: 19741500 | K48: =I48-I47/I47 -> 105.95
B49: Google | C49: GOOG | D49: 45027 | E49: 106.92 | F49: 107.22 | G49: 105.28 | H49: 106.12 | I49: 106.12 | J49: 18721300 | K49: =I49-I48/I48 -> 105.12
B50: Google | C50: GOOG | D50: 45028 | E50: 107.39 | F50: 107.587 | G50: 104.97 | H50: 105.22 | I50: 105.22 | J50: 22761600 | K50: =I50-I49/I49 -> 104.22
B51: Google | C51: GOOG | D51: 45029 | E51: 106.47 | F51: 108.265 | G51: 106.44 | H51: 108.19 | I51: 108.19 | J51: 21650700 | K51: =I51-I50/I50 -> 107.19
B52: Google | C52: GOOG | D52: 45030 | E52: 107.69 | F52: 109.58 | G52: 107.59 | H52: 109.46 | I52: 109.46 | J52: 20745400 | K52: =I52-I51/I51 -> 108.46
B53: Google | C53: GOOG | D53: 45033 | E53: 105.43 | F53: 106.71 | G53: 105.32 | H53: 106.42 | I53: 106.42 | J53: 29043400 | K53: =I53-I52/I52 -> 105.42
...

Sheet Stock Adjusted Close data
B3: Stocks Adjusted Close Data
C6: AAPL | D6: NSFT | E6: MSFT | F6: GOOG
B7: Date | C7: Adj. close | D7: =C7 -> Adj. close | E7: =C7 -> Adj. close | F7: =D7 -> Adj. close
B9: ='Apple Stock'!D10 -> 44964 | C9: ='Apple Stock'!I10 -> 154.41423 | D9: ='Netflix Stock'!I6 -> 362.95001 | E9: ='Microsoft Stock'!I6 -> 266.89151 | F9: ='Google Stock'!I6 -> 108.04 | I9: Correlation Matrix of Adjusted close Price
B10: ='Apple Stock'!D11 -> 44965 | C10: ='Apple Stock'!I11 -> 151.6884 | D10: ='Netflix Stock'!I7 -> 366.82999 | E10: ='Microsoft Stock'!I7 -> 266.0636 | F10: ='Google Stock'!I7 -> 100
B11: ='Apple Stock'!D12 -> 44966 | C11: ='Apple Stock'!I12 -> 150.64 | D11: ='Netflix Stock'!I8 -> 362.5 | E11: ='Microsoft Stock'!I8 -> 262.96136 | F11: ='Google Stock'!I8 -> 95.459999 | I11: AAPL | J11: NSFT | K11: MSFT | L11: GOOG
B12: ='Apple Stock'!D13 -> 44967 | C12: ='Apple Stock'!I13 -> 151.00999 | D12: ='Netflix Stock'!I9 -> 347.35999 | E12: ='Microsoft Stock'!I9 -> 262.44266 | F12: ='Google Stock'!I9 -> 94.860001 | H12: AAPL | I12: 1
B13: ='Apple Stock'!D14 -> 44970 | C13: ='Apple Stock'!I14 -> 153.85001 | D13: ='Netflix Stock'!I10 -> 358.57001 | E13: ='Microsoft Stock'!I10 -> 270.64212 | F13: ='Google Stock'!I10 -> 95 | H13: NSFT | I13: 0.071510761 | J13: 1
B14: ='Apple Stock'!D15 -> 44971 | C14: ='Apple Stock'!I15 -> 153.2 | D14: ='Netflix Stock'!I11 -> 359.95999 | E14: ='Microsoft Stock'!I11 -> 271.49002 | F14: ='Google Stock'!I11 -> 94.949997 | H14: MSFT | I14: 0.067009839 | J14: 0.20568071 | K14: 1
B15: ='Apple Stock'!D16 -> 44972 | C15: ='Apple Stock'!I16 -> 155.33 | D15: ='Netflix Stock'!I12 -> 361.42001 | E15: ='Microsoft Stock'!I12 -> 269.32001 | F15: ='Google Stock'!I12 -> 97.099998 | H15: GOOG | I15: 0.19259823 | J15: 0.17078069 | K15: 0.90568531 | L15: 1
B16: ='Apple Stock'!D17 -> 44973 | C16: ='Apple Stock'!I17 -> 153.71001 | D16: ='Netflix Stock'!I13 -> 350.70999 | E16: ='Microsoft Stock'!I13 -> 262.14999 | F16: ='Google Stock'!I13 -> 95.779999
B17: ='Apple Stock'!D18 -> 44974 | C17: ='Apple Stock'!I18 -> 152.55 | D17: ='Netflix Stock'!I14 -> 347.95999 | E17: ='Microsoft Stock'!I14 -> 258.06 | F17: ='Google Stock'!I14 -> 94.589996
B18: ='Apple Stock'!D19 -> 44978 | C18: ='Apple Stock'!I19 -> 148.48 | D18: ='Netflix Stock'!I15 -> 337.5 | E18: ='Microsoft Stock'!I15 -> 252.67 | F18: ='Google Stock'!I15 -> 92.050003 | I18: Green = strong positive
B19: ='Apple Stock'!D20 -> 44979 | C19: ='Apple Stock'!I20 -> 148.91 | D19: ='Netflix Stock'!I16 -> 334.88 | E19: ='Microsoft Stock'!I16 -> 251.50999 | F19: ='Google Stock'!I16 -> 91.800003 | I19: Red = weak/negative
B20: ='Apple Stock'!D21 -> 44980 | C20: ='Apple Stock'!I21 -> 149.39999 | D20: ='Netflix Stock'!I17 -> 323.64999 | E20: ='Microsoft Stock'!I17 -> 254.77 | F20: ='Google Stock'!I17 -> 91.07
B21: ='Apple Stock'!D22 -> 44981 | C21: ='Apple Stock'!I22 -> 146.71001 | D21: ='Netflix Stock'!I18 -> 317.14999 | E21: ='Microsoft Stock'!I18 -> 249.22 | F21: ='Google Stock'!I18 -> 89.349998
B22: ='Apple Stock'!D23 -> 44984 | C22: ='Apple Stock'!I23 -> 147.92 | D22: ='Netflix Stock'!I19 -> 323.03 | E22: ='Microsoft Stock'!I19 -> 250.16 | F22: ='Google Stock'!I19 -> 90.099998
B23: ='Apple Stock'!D24 -> 44985 | C23: ='Apple Stock'!I24 -> 147.41 | D23: ='Netflix Stock'!I20 -> 322.13 | E23: ='Microsoft Stock'!I20 -> 249.42 | F23: ='Google Stock'!I20 -> 90.300003
B24: ='Apple Stock'!D25 -> 44986 | C24: ='Apple Stock'!I25 -> 145.31 | D24: ='Netflix Stock'!I21 -> 313.48001 | E24: ='Microsoft Stock'!I21 -> 246.27 | F24: ='Google Stock'!I21 -> 90.510002
B25: ='Apple Stock'!D26 -> 44987 | C25: ='Apple Stock'!I26 -> 145.91 | D25: ='Netflix Stock'!I22 -> 311.88 | E25: ='Microsoft Stock'!I22 -> 251.11 | F25: ='Google Stock'!I22 -> 92.309998
B26: ='Apple Stock'!D27 -> 44988 | C26: ='Apple Stock'!I27 -> 151.03 | D26: ='Netflix Stock'!I23 -> 315.17999 | E26: ='Microsoft Stock'!I23 -> 255.28999 | F26: ='Google Stock'!I23 -> 94.019997
B27: ='Apple Stock'!D28 -> 44991 | C27: ='Apple Stock'!I28 -> 153.83 | D27: ='Netflix Stock'!I24 -> 312.03 | E27: ='Microsoft Stock'!I24 -> 256.87 | F27: ='Google Stock'!I24 -> 95.580002
B28: ='Apple Stock'!D29 -> 44992 | C28: ='Apple Stock'!I29 -> 151.60001 | D28: ='Netflix Stock'!I25 -> 308.47 | E28: ='Microsoft Stock'!I25 -> 254.14999 | F28: ='Google Stock'!I25 -> 94.169998
B29: ='Apple Stock'!D30 -> 44993 | C29: ='Apple Stock'!I30 -> 152.87 | D29: ='Netflix Stock'!I26 -> 311.79001 | E29: ='Microsoft Stock'!I26 -> 253.7 | F29: ='Google Stock'!I26 -> 94.650002
B30: ='Apple Stock'!D31 -> 44994 | C30: ='Apple Stock'!I31 -> 150.59 | D30: ='Netflix Stock'!I27 -> 297.78 | E30: ='Microsoft Stock'!I27 -> 252.32001 | F30: ='Google Stock'!I27 -> 92.660004
B31: ='Apple Stock'!D32 -> 44995 | C31: ='Apple Stock'!I32 -> 148.5 | D31: ='Netflix Stock'!I28 -> 292.76001 | E31: ='Microsoft Stock'!I28 -> 248.59 | F31: ='Google Stock'!I28 -> 91.010002
... B70: ='Apple Stock'!D71 -> 45051 | C70: ='Apple Stock'!I71 -> 173.57001 | D70: ='Netflix Stock'!I67 -> 322.76001 | E70: ='Microsoft Stock'!I67 -> 310.64999 | F70: ='Google Stock'!I67 -> 106.215

Sheet Volume Analysis
B3: Volume Analysis
B5: Company | D5: Average volume
B7: ='Stock Adjusted Close data'!C6 -> AAPL | D7: =AVERAGE('Apple Stock'!J10:J71) -> 60282958
B8: ='Stock Adjusted Close data'!D6 -> NSFT | D8: =AVERAGE('Netflix Stock'!J6:J67) -> 6471732.3
B9: ='Stock Adjusted Close data'!E6 -> MSFT | D9: =AVERAGE('Microsoft Stock'!J6:J67) -> 30848353
B10: ='Stock Adjusted Close data'!F6 -> GOOG | D10: =AVERAGE('Google Stock'!J6:J67) -> 30725373
